<?xml version="1.0" encoding="utf-8"?>
<!-- This URDF was automatically created by SolidWorks to URDF Exporter! Originally created by Stephen Brawner (brawner@gmail.com) 
     Commit Version: 1.5.0-0-g9aa0fdb  Build Version: 1.5.7004.21443
     For more information, please see http://wiki.ros.org/sw_urdf_exporter -->
<robot
  name="bubot_description">
  <link
    name="base_link">
    <inertial>
      <origin
        xyz="0.00614507467316344 0.00132442548214557 0.111279328924944"
        rpy="0 0 0" />
      <mass
        value="17.5407923723636" />
      <inertia
        ixx="0.469469086185873"
        ixy="0.000459258543047036"
        ixz="0.0195713811597716"
        iyy="0.488079163056402"
        iyz="-0.00170511359318661"
        izz="0.269766482328618" />
    </inertial>
    <visual>
      <origin
        xyz="0 0 0"
        rpy="0 0 0" />
      <geometry>
        <mesh
          filename="package://bubot_description/meshes/base_link.STL" />
      </geometry>
      <material
        name="">
        <color
          rgba="0.792156862745098 0.819607843137255 0.933333333333333 1" />
      </material>
    </visual>
    <collision>
      <origin
        xyz="0 0 0"
        rpy="0 0 0" />
      <geometry>
        <mesh
          filename="package://bubot_description/meshes/base_link.STL" />
      </geometry>
    </collision>
  </link>
  <link
    name="left_wheel_link">
    <inertial>
      <origin
        xyz="-7.84851523104154E-11 -0.00332107438012788 8.73111291599393E-10"
        rpy="0 0 0" />
      <mass
        value="0.287293505141149" />
      <inertia
        ixx="0.000307503313942651"
        ixy="2.95562518254029E-12"
        ixz="-1.22548541274726E-17"
        iyy="0.000432551955047046"
        iyz="-3.80638695771607E-11"
        izz="0.000307503317768079" />
    </inertial>
    <visual>
      <origin
        xyz="0 0 0"
        rpy="0 0 0" />
      <geometry>
        <mesh
          filename="package://bubot_description/meshes/left_wheel_link.STL" />
      </geometry>
      <material
        name="">
        <color
          rgba="0.752941176470588 0.752941176470588 0.752941176470588 1" />
      </material>
    </visual>
    <collision>
      <origin
        xyz="0 0 0"
        rpy="0 0 0" />
      <geometry>
        <mesh
          filename="package://bubot_description/meshes/left_wheel_link.STL" />
      </geometry>
    </collision>
  </link>
  <joint
    name="left_wheel_joint"
    type="continuous">
    <origin
      xyz="0 0.1795 -0.0814300000000002"
      rpy="0 0 0" />
    <parent
      link="base_link" />
    <child
      link="left_wheel_link" />
    <axis
      xyz="0 -0.999999999999957 0" />
    
      
  </joint>
  <link
    name="right_wheel_link">
    <inertial>
      <origin
        xyz="4.93461377815295E-11 0.00299505405611283 7.77355430026105E-10"
        rpy="0 0 0" />
      <mass
        value="0.287293505141148" />
      <inertia
        ixx="0.00030858947346633"
        ixy="2.0428470969486E-12"
        ixz="1.19749316134548E-17"
        iyy="0.000432551955047045"
        iyz="3.77544364458498E-11"
        izz="0.000308589477291759" />
    </inertial>
    <visual>
      <origin
        xyz="0 0 0"
        rpy="0 0 0" />
      <geometry>
        <mesh
          filename="package://bubot_description/meshes/right_wheel_link.STL" />
      </geometry>
      <material
        name="">
        <color
          rgba="0.752941176470588 0.752941176470588 0.752941176470588 1" />
      </material>
    </visual>
    <collision>
      <origin
        xyz="0 0 0"
        rpy="0 0 0" />
      <geometry>
        <mesh
          filename="package://bubot_description/meshes/right_wheel_link.STL" />
      </geometry>
    </collision>
  </link>
  <joint
    name="right_wheel_joint"
    type="continuous">
    <origin
      xyz="0 -0.1795 -0.08143"
      rpy="0 0 0" />
    <parent
      link="base_link" />
    <child
      link="right_wheel_link" />
    <axis
      xyz="0 1 0" />
    
      
  </joint>
  <link
    name="left_front_wheel_link">
    <inertial>
      <origin
        xyz="-1.69586567011493E-14 -0.00184263548561878 -2.8047009159593E-14"
        rpy="0 0 0" />
      <mass
        value="0.292526122406118" />
      <inertia
        ixx="0.000182324161031027"
        ixy="-1.25120058784725E-20"
        ixz="-1.04220518069559E-21"
        iyy="0.000310962059892664"
        iyz="-1.5008782043789E-21"
        izz="0.000182324161031027" />
    </inertial>
    <visual>
      <origin
        xyz="0 0 0"
        rpy="0 0 0" />
      <geometry>
        <mesh
          filename="package://bubot_description/meshes/left_front_wheel_link.STL" />
      </geometry>
      <material
        name="">
        <color
          rgba="0.752941176470588 0.752941176470588 0.752941176470588 1" />
      </material>
    </visual>
    <collision>
      <origin
        xyz="0 0 0"
        rpy="0 0 0" />
      <geometry>
        <mesh
          filename="package://bubot_description/meshes/left_front_wheel_link.STL" />
      </geometry>
    </collision>
  </link>
  <joint
    name="left_front_wheel_joint"
    type="continuous">
    <origin
      xyz="0.157 0.0873 -0.09493"
      rpy="0 0 0" />
    <parent
      link="base_link" />
    <child
      link="left_front_wheel_link" />
    <axis
      xyz="0 1 0" />
    
      
  </joint>
  <link
    name="right_front_wheel_link">
    <inertial>
      <origin
        xyz="-1.69309011255336E-14 0.00184263548561878 -2.80192535839774E-14"
        rpy="0 0 0" />
      <mass
        value="0.292526122406118" />
      <inertia
        ixx="0.000182324161031027"
        ixy="1.88302295403389E-21"
        ixz="-4.18630938134262E-21"
        iyy="0.000310962059892664"
        iyz="-4.00692203468122E-21"
        izz="0.000182324161031027" />
    </inertial>
    <visual>
      <origin
        xyz="0 0 0"
        rpy="0 0 0" />
      <geometry>
        <mesh
          filename="package://bubot_description/meshes/right_front_wheel_link.STL" />
      </geometry>
      <material
        name="">
        <color
          rgba="0.752941176470588 0.752941176470588 0.752941176470588 1" />
      </material>
    </visual>
    <collision>
      <origin
        xyz="0 0 0"
        rpy="0 0 0" />
      <geometry>
        <mesh
          filename="package://bubot_description/meshes/right_front_wheel_link.STL" />
      </geometry>
    </collision>
  </link>
  <joint
    name="right_front_wheel_joint"
    type="continuous">
    <origin
      xyz="0.157 -0.0873 -0.09493"
      rpy="0 0 0" />
    <parent
      link="base_link" />
    <child
      link="right_front_wheel_link" />
    <axis
      xyz="0 -1 0" />
    
      
  </joint>
  <link
    name="rear_wheel_link">
    <inertial>
      <origin
        xyz="0 0.0018426354861247 0"
        rpy="0 0 0" />
      <mass
        value="0.292526122406118" />
      <inertia
        ixx="0.000182324161031027"
        ixy="9.01577989152663E-21"
        ixz="-6.34838413139654E-21"
        iyy="0.000310962059892664"
        iyz="-1.24832850142728E-20"
        izz="0.000182324161031027" />
    </inertial>
    <visual>
      <origin
        xyz="0 0 0"
        rpy="0 0 0" />
      <geometry>
        <mesh
          filename="package://bubot_description/meshes/rear_wheel_link.STL" />
      </geometry>
      <material
        name="">
        <color
          rgba="0.752941176470588 0.752941176470588 0.752941176470588 1" />
      </material>
    </visual>
    <collision>
      <origin
        xyz="0 0 0"
        rpy="0 0 0" />
      <geometry>
        <mesh
          filename="package://bubot_description/meshes/rear_wheel_link.STL" />
      </geometry>
    </collision>
  </link>
  <joint
    name="rear_wheel_joint"
    type="continuous">
    <origin
      xyz="-0.156999999999998 0 -0.0949300000000002"
      rpy="0 0 0" />
    <parent
      link="base_link" />
    <child
      link="rear_wheel_link" />
    <axis
      xyz="0 -1 0" />
    
      
  </joint>
  <link
    name="front_laser_mountpoint_link">
    <inertial>
      <origin
        xyz="0.0109910978700271 -0.00660628943773737 -0.0102231270512427"
        rpy="0 0 0" />
      <mass
        value="0.142293449327418" />
      <inertia
        ixx="7.99749503749484E-05"
        ixy="7.56325152192464E-08"
        ixz="2.6339172338324E-08"
        iyy="8.01694611303598E-05"
        iyz="1.99081597083217E-07"
        izz="4.9027575487778E-05" />
    </inertial>
    <visual>
      <origin
        xyz="0 0 0"
        rpy="0 0 0" />
      <geometry>
        <mesh
          filename="package://bubot_description/meshes/front_laser_mountpoint_link.STL" />
      </geometry>
      <material
        name="">
        <color
          rgba="0.752941176470588 0.752941176470588 0.752941176470588 1" />
      </material>
    </visual>
    <collision>
      <origin
        xyz="0 0 0"
        rpy="0 0 0" />
      <geometry>
        <mesh
          filename="package://bubot_description/meshes/front_laser_mountpoint_link.STL" />
      </geometry>
    </collision>
  </link>
  <joint
    name="front_laser_mountpoint_joint"
    type="fixed">
    <origin
      xyz="0.169930018642521 0.00655022800475659 -0.0313817529714081"
      rpy="0 0 0" />
    <parent
      link="base_link" />
    <child
      link="front_laser_mountpoint_link" />
    <axis
      xyz="0 0 0" />
    
      
  </joint>
  <link
    name="torso_yaw_link">
    <inertial>
      <origin
        xyz="-0.0211836539763696 3.71816208305583E-05 0.134250337044029"
        rpy="0 0 0" />
      <mass
        value="15.384134203599" />
      <inertia
        ixx="0.502071562161703"
        ixy="-4.51403345740403E-06"
        ixz="-0.036488125429086"
        iyy="0.466071581377529"
        iyz="9.71646967407404E-05"
        izz="0.120092843605433" />
    </inertial>
    <visual>
      <origin
        xyz="0 0 0"
        rpy="0 0 0" />
      <geometry>
        <mesh
          filename="package://bubot_description/meshes/torso_yaw_link.STL" />
      </geometry>
      <material
        name="">
        <color
          rgba="0.792156862745098 0.819607843137255 0.933333333333333 1" />
      </material>
    </visual>
    <collision>
      <origin
        xyz="0 0 0"
        rpy="0 0 0" />
      <geometry>
        <mesh
          filename="package://bubot_description/meshes/torso_yaw_link.STL" />
      </geometry>
    </collision>
  </link>
  <joint
    name="torso_yaw_joint"
    type="revolute">
    <origin
      xyz="0 0 0.5265"
      rpy="0 0 0" />
    <parent
      link="base_link" />
    <child
      link="torso_yaw_link" />
    <axis
      xyz="0 0 1" />
    <limit
      lower="-0.79"
      upper="0.79"
      effort="10"
      velocity="1" />
    
      
  </joint>
  <link
    name="tray_pitch_link">
    <inertial>
      <origin
        xyz="0.0621721863824356 0.000728335369562271 0.180477032954461"
        rpy="0 0 0" />
      <mass
        value="2.98068027802018" />
      <inertia
        ixx="0.0194947536832028"
        ixy="-7.48678413809687E-05"
        ixz="-0.00132900861679371"
        iyy="0.011613140525037"
        iyz="-5.37259655538909E-05"
        izz="0.0142243951256448" />
    </inertial>
    <visual>
      <origin
        xyz="0 0 0"
        rpy="0 0 0" />
      <geometry>
        <mesh
          filename="package://bubot_description/meshes/tray_pitch_link.STL" />
      </geometry>
      <material
        name="">
        <color
          rgba="0.792156862745098 0.819607843137255 0.933333333333333 1" />
      </material>
    </visual>
    <collision>
      <origin
        xyz="0 0 0"
        rpy="0 0 0" />
      <geometry>
        <mesh
          filename="package://bubot_description/meshes/tray_pitch_link.STL" />
      </geometry>
    </collision>
  </link>
  <joint
    name="tray_pitch_joint"
    type="revolute">
    <origin
      xyz="0.02548 0 0.028"
      rpy="0 0 0" />
    <parent
      link="torso_yaw_link" />
    <child
      link="tray_pitch_link" />
    <axis
      xyz="0 1 0" />
    <limit
      lower="-1.57"
      upper="0"
      effort="10"
      velocity="1" />
    
      
  </joint>
  <link
    name="head_yaw_link">
    <inertial>
      <origin
        xyz="0.0014962219880101 -3.04882859083288E-05 0.00782467988013213"
        rpy="0 0 0" />
      <mass
        value="0.201333205297474" />
      <inertia
        ixx="0.000736239714581384"
        ixy="-1.14109916065634E-08"
        ixz="-9.99042992566853E-06"
        iyy="0.00072938836390482"
        iyz="-1.17463954570097E-07"
        izz="5.17097177907421E-05" />
    </inertial>
    <visual>
      <origin
        xyz="0 0 0"
        rpy="0 0 0" />
      <geometry>
        <mesh
          filename="package://bubot_description/meshes/head_yaw_link.STL" />
      </geometry>
      <material
        name="">
        <color
          rgba="0.752941176470588 0.752941176470588 0.752941176470588 1" />
      </material>
    </visual>
    <collision>
      <origin
        xyz="0 0 0"
        rpy="0 0 0" />
      <geometry>
        <mesh
          filename="package://bubot_description/meshes/head_yaw_link.STL" />
      </geometry>
    </collision>
  </link>
  <joint
    name="head_yaw_joint"
    type="revolute">
    <origin
      xyz="0 0 0.30737"
      rpy="0 0 0" />
    <parent
      link="torso_yaw_link" />
    <child
      link="head_yaw_link" />
    <axis
      xyz="0 0 1" />
    <limit
      lower="-0.79"
      upper="0.79"
      effort="10"
      velocity="1" />
    
      
  </joint>
  <link
    name="head_pitch_link">
    <inertial>
      <origin
        xyz="0.00135536661040343 -0.000122880868704684 0.251021558465587"
        rpy="0 0 0" />
      <mass
        value="5.58924337729417" />
      <inertia
        ixx="0.0614222666404918"
        ixy="-9.13342160102728E-06"
        ixz="0.00139479623362596"
        iyy="0.0627976215444188"
        iyz="-5.50046240195658E-05"
        izz="0.0288452581063919" />
    </inertial>
    <visual>
      <origin
        xyz="0 0 0"
        rpy="0 0 0" />
      <geometry>
        <mesh
          filename="package://bubot_description/meshes/head_pitch_link.STL" />
      </geometry>
      <material
        name="">
        <color
          rgba="0.752941176470588 0.752941176470588 0.752941176470588 1" />
      </material>
    </visual>
    <collision>
      <origin
        xyz="0 0 0"
        rpy="0 0 0" />
      <geometry>
        <mesh
          filename="package://bubot_description/meshes/head_pitch_link.STL" />
      </geometry>
    </collision>
  </link>
  <joint
    name="head_pitch_joint"
    type="revolute">
    <origin
      xyz="0 0 0.0545"
      rpy="0 0 0" />
    <parent
      link="head_yaw_link" />
    <child
      link="head_pitch_link" />
    <axis
      xyz="0 -1 0" />
    <limit
      lower="-0.4"
      upper="0.4"
      effort="10"
      velocity="1" />
    
      
  </joint>
  <link
    name="left_camera_link">
    <inertial>
      <origin
        xyz="-0.0267186601902245 5.79327189692558E-09 -0.00151976594563874"
        rpy="0 0 0" />
      <mass
        value="0.040493403492273" />
      <inertia
        ixx="5.29997303158495E-06"
        ixy="3.00820822720973E-12"
        ixz="-4.20967409707152E-07"
        iyy="1.30948609116678E-05"
        iyz="2.95114820905194E-12"
        izz="1.19423729648629E-05" />
    </inertial>
    <visual>
      <origin
        xyz="0 0 0"
        rpy="0 0 0" />
      <geometry>
        <mesh
          filename="package://bubot_description/meshes/left_camera_link.STL" />
      </geometry>
      <material
        name="">
        <color
          rgba="0.792156862745098 0.819607843137255 0.933333333333333 1" />
      </material>
    </visual>
    <collision>
      <origin
        xyz="0 0 0"
        rpy="0 0 0" />
      <geometry>
        <mesh
          filename="package://bubot_description/meshes/left_camera_link.STL" />
      </geometry>
    </collision>
  </link>
  <joint
    name="left_camera_joint"
    type="fixed">
    <origin
      xyz="0.06349 0.034249 0.13677"
      rpy="0 0 0" />
    <parent
      link="head_pitch_link" />
    <child
      link="left_camera_link" />
    <axis
      xyz="0 0 0" />
    
      
  </joint>
  <link
    name="right_camera_link">
    <inertial>
      <origin
        xyz="-0.0267186601902246 5.79327180671996E-09 -0.00151976594563896"
        rpy="0 0 0" />
      <mass
        value="0.0404934034922726" />
      <inertia
        ixx="5.29997303158491E-06"
        ixy="3.00820827741918E-12"
        ixz="-4.20967409707142E-07"
        iyy="1.30948609116678E-05"
        iyz="2.95114823210664E-12"
        izz="1.19423729648629E-05" />
    </inertial>
    <visual>
      <origin
        xyz="0 0 0"
        rpy="0 0 0" />
      <geometry>
        <mesh
          filename="package://bubot_description/meshes/right_camera_link.STL" />
      </geometry>
      <material
        name="">
        <color
          rgba="0.792156862745098 0.819607843137255 0.933333333333333 1" />
      </material>
    </visual>
    <collision>
      <origin
        xyz="0 0 0"
        rpy="0 0 0" />
      <geometry>
        <mesh
          filename="package://bubot_description/meshes/right_camera_link.STL" />
      </geometry>
    </collision>
  </link>
  <joint
    name="right_camera_joint"
    type="fixed">
    <origin
      xyz="0.06349 -0.034249 0.13677"
      rpy="0 0 0" />
    <parent
      link="head_pitch_link" />
    <child
      link="right_camera_link" />
    <axis
      xyz="0 0 0" />
    
      
  </joint>
  <link
    name="left_arm_shoulder_pitch_link">
    <inertial>
      <origin
        xyz="-2.01847045650135E-05 -0.0451116289125171 -2.35599322817581E-06"
        rpy="0 0 0" />
      <mass
        value="0.306747657838696" />
      <inertia
        ixx="0.000644985216105913"
        ixy="-3.96276186346391E-07"
        ixz="8.03414796312445E-09"
        iyy="0.000167167127049386"
        iyz="-4.26302036483178E-08"
        izz="0.000757573229516701" />
    </inertial>
    <visual>
      <origin
        xyz="0 0 0"
        rpy="0 0 0" />
      <geometry>
        <mesh
          filename="package://bubot_description/meshes/left_arm_shoulder_pitch_link.STL" />
      </geometry>
      <material
        name="">
        <color
          rgba="0.752941176470588 0.752941176470588 0.752941176470588 1" />
      </material>
    </visual>
    <collision>
      <origin
        xyz="0 0 0"
        rpy="0 0 0" />
      <geometry>
        <mesh
          filename="package://bubot_description/meshes/left_arm_shoulder_pitch_link.STL" />
      </geometry>
    </collision>
  </link>
  <joint
    name="left_arm_shoulder_pitch_joint"
    type="revolute">
    <origin
      xyz="0 0.17524 0.28577"
      rpy="0 0 0" />
    <parent
      link="torso_yaw_link" />
    <child
      link="left_arm_shoulder_pitch_link" />
    <axis
      xyz="0 -1 0" />
    <limit
      lower="-0.52"
      upper="2.62"
      effort="10"
      velocity="1" />
    
      
  </joint>
  <link
    name="left_arm_shoulder_roll_link">
    <inertial>
      <origin
        xyz="-0.00935726062318225 1.85211083744696E-06 -0.0749352243453262"
        rpy="0 0 0" />
      <mass
        value="0.148223892772267" />
      <inertia
        ixx="0.000205311872027797"
        ixy="4.49394119027176E-10"
        ixz="-3.57142199446871E-05"
        iyy="0.000287705166912236"
        iyz="5.8749575095666E-09"
        izz="0.000108432879463927" />
    </inertial>
    <visual>
      <origin
        xyz="0 0 0"
        rpy="0 0 0" />
      <geometry>
        <mesh
          filename="package://bubot_description/meshes/left_arm_shoulder_roll_link.STL" />
      </geometry>
      <material
        name="">
        <color
          rgba="0.752941176470588 0.752941176470588 0.752941176470588 1" />
      </material>
    </visual>
    <collision>
      <origin
        xyz="0 0 0"
        rpy="0 0 0" />
      <geometry>
        <mesh
          filename="package://bubot_description/meshes/left_arm_shoulder_roll_link.STL" />
      </geometry>
    </collision>
  </link>
  <joint
    name="left_arm_shoulder_roll_joint"
    type="revolute">
    <origin
      xyz="0 0 0"
      rpy="0 0 0" />
    <parent
      link="left_arm_shoulder_pitch_link" />
    <child
      link="left_arm_shoulder_roll_link" />
    <axis
      xyz="1 0 0" />
    <limit
      lower="-1.57"
      upper="0.8"
      effort="10"
      velocity="1" />
    
      
  </joint>
  <link
    name="left_arm_shoulder_yaw_link">
    <inertial>
      <origin
        xyz="-4.01901055222955E-05 0.00197241738066228 -0.0389134846245449"
        rpy="0 0 0" />
      <mass
        value="0.152725889069381" />
      <inertia
        ixx="0.000108787432464282"
        ixy="-1.43335608439823E-08"
        ixz="2.92942408618662E-07"
        iyy="0.000115714604896234"
        iyz="1.37835570785637E-06"
        izz="5.03538269720473E-05" />
    </inertial>
    <visual>
      <origin
        xyz="0 0 0"
        rpy="0 0 0" />
      <geometry>
        <mesh
          filename="package://bubot_description/meshes/left_arm_shoulder_yaw_link.STL" />
      </geometry>
      <material
        name="">
        <color
          rgba="0.752941176470588 0.752941176470588 0.752941176470588 1" />
      </material>
    </visual>
    <collision>
      <origin
        xyz="0 0 0"
        rpy="0 0 0" />
      <geometry>
        <mesh
          filename="package://bubot_description/meshes/left_arm_shoulder_yaw_link.STL" />
      </geometry>
    </collision>
  </link>
  <joint
    name="left_arm_shoulder_yaw_joint"
    type="revolute">
    <origin
      xyz="0 0 -0.1284"
      rpy="0 0 0" />
    <parent
      link="left_arm_shoulder_roll_link" />
    <child
      link="left_arm_shoulder_yaw_link" />
    <axis
      xyz="0 0 1" />
    <limit
      lower="-1.57"
      upper="1.57"
      effort="10"
      velocity="1" />
    
      
  </joint>
  <link
    name="left_arm_elbow_roll_link">
    <inertial>
      <origin
        xyz="-0.0133479498953629 -1.74693127491521E-07 -0.0554210342087247"
        rpy="0 0 0" />
      <mass
        value="0.225143095717014" />
      <inertia
        ixx="9.98807488182808E-05"
        ixy="2.45099920488333E-10"
        ixz="-1.60210737229541E-05"
        iyy="0.000150288035346698"
        iyz="5.4288554667378E-10"
        izz="9.03563982672108E-05" />
    </inertial>
    <visual>
      <origin
        xyz="0 0 0"
        rpy="0 0 0" />
      <geometry>
        <mesh
          filename="package://bubot_description/meshes/left_arm_elbow_roll_link.STL" />
      </geometry>
      <material
        name="">
        <color
          rgba="0.752941176470588 0.752941176470588 0.752941176470588 1" />
      </material>
    </visual>
    <collision>
      <origin
        xyz="0 0 0"
        rpy="0 0 0" />
      <geometry>
        <mesh
          filename="package://bubot_description/meshes/left_arm_elbow_roll_link.STL" />
      </geometry>
    </collision>
  </link>
  <joint
    name="left_arm_elbow_roll_joint"
    type="revolute">
    <origin
      xyz="0 0 -0.057"
      rpy="0 0 0" />
    <parent
      link="left_arm_shoulder_yaw_link" />
    <child
      link="left_arm_elbow_roll_link" />
    <axis
      xyz="1 0 0" />
    <limit
      lower="-1.57"
      upper="0"
      effort="10"
      velocity="1" />
    
      
  </joint>
  <link
    name="left_arm_forearm_yaw_link">
    <inertial>
      <origin
        xyz="-6.6970770083286E-05 0.00116472445725802 -0.0378005926629413"
        rpy="0 0 0" />
      <mass
        value="0.258905060533676" />
      <inertia
        ixx="0.000139306913841423"
        ixy="-2.0253581906963E-08"
        ixz="7.15620929206833E-07"
        iyy="0.000149549619429831"
        iyz="9.41595146498601E-07"
        izz="7.19910419186781E-05" />
    </inertial>
    <visual>
      <origin
        xyz="0 0 0"
        rpy="0 0 0" />
      <geometry>
        <mesh
          filename="package://bubot_description/meshes/left_arm_forearm_yaw_link.STL" />
      </geometry>
      <material
        name="">
        <color
          rgba="0.752941176470588 0.752941176470588 0.752941176470588 1" />
      </material>
    </visual>
    <collision>
      <origin
        xyz="0 0 0"
        rpy="0 0 0" />
      <geometry>
        <mesh
          filename="package://bubot_description/meshes/left_arm_forearm_yaw_link.STL" />
      </geometry>
    </collision>
  </link>
  <joint
    name="left_arm_forearm_yaw_joint"
    type="revolute">
    <origin
      xyz="0 0 -0.0859"
      rpy="0 0 0" />
    <parent
      link="left_arm_elbow_roll_link" />
    <child
      link="left_arm_forearm_yaw_link" />
    <axis
      xyz="0 0 1" />
    <limit
      lower="-1.57"
      upper="1.57"
      effort="10"
      velocity="1" />
    
      
  </joint>
  <link
    name="left_arm_wrist_roll_link">
    <inertial>
      <origin
        xyz="7.35434333757039E-05 -0.00440529803418652 -0.0544053642249812"
        rpy="0 0 0" />
      <mass
        value="0.280294928579261" />
      <inertia
        ixx="0.000132795074211678"
        ixy="-2.96287980415066E-07"
        ixz="3.42523704486071E-07"
        iyy="0.000117756363395381"
        iyz="-1.48425806925107E-05"
        izz="9.47251038940315E-05" />
    </inertial>
    <visual>
      <origin
        xyz="0 0 0"
        rpy="0 0 0" />
      <geometry>
        <mesh
          filename="package://bubot_description/meshes/left_arm_wrist_roll_link.STL" />
      </geometry>
      <material
        name="">
        <color
          rgba="0.752941176470588 0.752941176470588 0.752941176470588 1" />
      </material>
    </visual>
    <collision>
      <origin
        xyz="0 0 0"
        rpy="0 0 0" />
      <geometry>
        <mesh
          filename="package://bubot_description/meshes/left_arm_wrist_roll_link.STL" />
      </geometry>
    </collision>
  </link>
  <joint
    name="left_arm_wrist_roll_joint"
    type="revolute">
    <origin
      xyz="0 0 -0.0545"
      rpy="0 0 0" />
    <parent
      link="left_arm_forearm_yaw_link" />
    <child
      link="left_arm_wrist_roll_link" />
    <axis
      xyz="1 0 0" />
    <limit
      lower="-1.57"
      upper="0.5"
      effort="10"
      velocity="1" />
    
      
  </joint>
  <link
    name="left_gripper_link">
    <inertial>
      <origin
        xyz="-0.000991234955939549 0.026129079228895 -0.021578203651113"
        rpy="0 0 0" />
      <mass
        value="0.0259118393412755" />
      <inertia
        ixx="2.26169168850478E-05"
        ixy="-6.71117975004994E-07"
        ixz="5.54229703889131E-07"
        iyy="2.68146617009823E-05"
        iyz="6.49688575835065E-06"
        izz="1.4469767247106E-05" />
    </inertial>
    <visual>
      <origin
        xyz="0 0 0"
        rpy="0 0 0" />
      <geometry>
        <mesh
          filename="package://bubot_description/meshes/left_gripper_link.STL" />
      </geometry>
      <material
        name="">
        <color
          rgba="0.752941176470588 0.752941176470588 0.752941176470588 1" />
      </material>
    </visual>
    <collision>
      <origin
        xyz="0 0 0"
        rpy="0 0 0" />
      <geometry>
        <mesh
          filename="package://bubot_description/meshes/left_gripper_link.STL" />
      </geometry>
    </collision>
  </link>
  <joint
    name="left_gripper_joint"
    type="revolute">
    <origin
      xyz="0.0001 0.008 -0.057"
      rpy="0 0 0" />
    <parent
      link="left_arm_wrist_roll_link" />
    <child
      link="left_gripper_link" />
    <axis
      xyz="1 0 0" />
    <limit
      lower="-1.57"
      upper="0"
      effort="10"
      velocity="1" />
    
      
  </joint>
  <link
    name="right_arm_shoulder_pitch_link">
    <inertial>
      <origin
        xyz="-2.01847045647611E-05 0.0451116289125171 2.35599323250568E-06"
        rpy="0 0 0" />
      <mass
        value="0.306747657838696" />
      <inertia
        ixx="0.000644985216105911"
        ixy="3.96276186342984E-07"
        ixz="-8.03414796694001E-09"
        iyy="0.000167167127049385"
        iyz="-4.26302037216061E-08"
        izz="0.000757573229516699" />
    </inertial>
    <visual>
      <origin
        xyz="0 0 0"
        rpy="0 0 0" />
      <geometry>
        <mesh
          filename="package://bubot_description/meshes/right_arm_shoulder_pitch_link.STL" />
      </geometry>
      <material
        name="">
        <color
          rgba="0.752941176470588 0.752941176470588 0.752941176470588 1" />
      </material>
    </visual>
    <collision>
      <origin
        xyz="0 0 0"
        rpy="0 0 0" />
      <geometry>
        <mesh
          filename="package://bubot_description/meshes/right_arm_shoulder_pitch_link.STL" />
      </geometry>
    </collision>
  </link>
  <joint
    name="right_arm_shoulder_pitch_joint"
    type="revolute">
    <origin
      xyz="0 -0.17524 0.28577"
      rpy="0 0 0" />
    <parent
      link="torso_yaw_link" />
    <child
      link="right_arm_shoulder_pitch_link" />
    <axis
      xyz="0 1 0" />
    <limit
      lower="-2.62"
      upper="0.52"
      effort="10"
      velocity="1" />
    
      
  </joint>
  <link
    name="right_arm_shoulder_roll_link">
    <inertial>
      <origin
        xyz="-0.00935726062318807 1.85250750658894E-06 -0.0749352247419803"
        rpy="0 0 0" />
      <mass
        value="0.148223892772287" />
      <inertia
        ixx="0.000205311863216038"
        ixy="4.48844260026596E-10"
        ixz="-3.57142193941647E-05"
        iyy="0.000287705165751563"
        iyz="5.87055159724753E-09"
        izz="0.000108432871812912" />
    </inertial>
    <visual>
      <origin
        xyz="0 0 0"
        rpy="0 0 0" />
      <geometry>
        <mesh
          filename="package://bubot_description/meshes/right_arm_shoulder_roll_link.STL" />
      </geometry>
      <material
        name="">
        <color
          rgba="0.752941176470588 0.752941176470588 0.752941176470588 1" />
      </material>
    </visual>
    <collision>
      <origin
        xyz="0 0 0"
        rpy="0 0 0" />
      <geometry>
        <mesh
          filename="package://bubot_description/meshes/right_arm_shoulder_roll_link.STL" />
      </geometry>
    </collision>
  </link>
  <joint
    name="right_arm_shoulder_roll_joint"
    type="revolute">
    <origin
      xyz="0 0 0"
      rpy="0 0 0" />
    <parent
      link="right_arm_shoulder_pitch_link" />
    <child
      link="right_arm_shoulder_roll_link" />
    <axis
      xyz="-1 0 0" />
    <limit
      lower="-0.8"
      upper="1.57"
      effort="10"
      velocity="1" />
    
      
  </joint>
  <link
    name="right_arm_shoulder_yaw_link">
    <inertial>
      <origin
        xyz="-2.54421664651325E-05 -0.00197652841663448 -0.0389134846245834"
        rpy="0 0 0" />
      <mass
        value="0.152725889069381" />
      <inertia
        ixx="0.000108784953072904"
        ixy="5.45342629693321E-09"
        ixz="3.95523713396294E-07"
        iyy="0.000115714752725992"
        iyz="-1.38311998572724E-06"
        izz="5.0351495410133E-05" />
    </inertial>
    <visual>
      <origin
        xyz="0 0 0"
        rpy="0 0 0" />
      <geometry>
        <mesh
          filename="package://bubot_description/meshes/right_arm_shoulder_yaw_link.STL" />
      </geometry>
      <material
        name="">
        <color
          rgba="0.752941176470588 0.752941176470588 0.752941176470588 1" />
      </material>
    </visual>
    <collision>
      <origin
        xyz="0 0 0"
        rpy="0 0 0" />
      <geometry>
        <mesh
          filename="package://bubot_description/meshes/right_arm_shoulder_yaw_link.STL" />
      </geometry>
    </collision>
  </link>
  <joint
    name="right_arm_shoulder_yaw_joint"
    type="revolute">
    <origin
      xyz="0 0 -0.1284"
      rpy="0 0 0" />
    <parent
      link="right_arm_shoulder_roll_link" />
    <child
      link="right_arm_shoulder_yaw_link" />
    <axis
      xyz="0 0 -1" />
    <limit
      lower="-1.57"
      upper="1.57"
      effort="10"
      velocity="1" />
    
      
  </joint>
  <link
    name="right_arm_elbow_roll_link">
    <inertial>
      <origin
        xyz="-0.0133479498953628 -1.74693131543835E-07 -0.0554210342087247"
        rpy="0 0 0" />
      <mass
        value="0.225143095717014" />
      <inertia
        ixx="9.98807488182809E-05"
        ixy="2.45099919047629E-10"
        ixz="-1.60210737229541E-05"
        iyy="0.000150288035346699"
        iyz="5.42885542318241E-10"
        izz="9.03563982672107E-05" />
    </inertial>
    <visual>
      <origin
        xyz="0 0 0"
        rpy="0 0 0" />
      <geometry>
        <mesh
          filename="package://bubot_description/meshes/right_arm_elbow_roll_link.STL" />
      </geometry>
      <material
        name="">
        <color
          rgba="0.752941176470588 0.752941176470588 0.752941176470588 1" />
      </material>
    </visual>
    <collision>
      <origin
        xyz="0 0 0"
        rpy="0 0 0" />
      <geometry>
        <mesh
          filename="package://bubot_description/meshes/right_arm_elbow_roll_link.STL" />
      </geometry>
    </collision>
  </link>
  <joint
    name="right_arm_elbow_roll_joint"
    type="revolute">
    <origin
      xyz="0 0 -0.057"
      rpy="0 0 0" />
    <parent
      link="right_arm_shoulder_yaw_link" />
    <child
      link="right_arm_elbow_roll_link" />
    <axis
      xyz="1 0 0" />
    <limit
      lower="0"
      upper="1.57"
      effort="10"
      velocity="1" />
    
      
  </joint>
  <link
    name="right_arm_forearm_yaw_link">
    <inertial>
      <origin
        xyz="-5.82710865038856E-05 -0.00116472501945633 -0.037800592662962"
        rpy="0 0 0" />
      <mass
        value="0.258905060533675" />
      <inertia
        ixx="0.000139306913502481"
        ixy="1.75134911845078E-08"
        ixz="8.15077015953276E-07"
        iyy="0.000149549901523719"
        iyz="-9.41602233040027E-07"
        izz="7.19913236733835E-05" />
    </inertial>
    <visual>
      <origin
        xyz="0 0 0"
        rpy="0 0 0" />
      <geometry>
        <mesh
          filename="package://bubot_description/meshes/right_arm_forearm_yaw_link.STL" />
      </geometry>
      <material
        name="">
        <color
          rgba="0.752941176470588 0.752941176470588 0.752941176470588 1" />
      </material>
    </visual>
    <collision>
      <origin
        xyz="0 0 0"
        rpy="0 0 0" />
      <geometry>
        <mesh
          filename="package://bubot_description/meshes/right_arm_forearm_yaw_link.STL" />
      </geometry>
    </collision>
  </link>
  <joint
    name="right_arm_forearm_yaw_joint"
    type="revolute">
    <origin
      xyz="0 0 -0.0859"
      rpy="0 0 0" />
    <parent
      link="right_arm_elbow_roll_link" />
    <child
      link="right_arm_forearm_yaw_link" />
    <axis
      xyz="0 0 -1" />
    <limit
      lower="-1.57"
      upper="1.57"
      effort="10"
      velocity="1" />
    
      
  </joint>
  <link
    name="right_arm_wrist_roll_link">
    <inertial>
      <origin
        xyz="-0.000136224402740855 0.00440529803529258 -0.0544053636252678"
        rpy="0 0 0" />
      <mass
        value="0.280294928567053" />
      <inertia
        ixx="0.000132795073332597"
        ixy="6.39250660584392E-07"
        ixz="1.89973116759433E-07"
        iyy="0.000117752677076981"
        iyz="1.48425857231549E-05"
        izz="9.47214184411057E-05" />
    </inertial>
    <visual>
      <origin
        xyz="0 0 0"
        rpy="0 0 0" />
      <geometry>
        <mesh
          filename="package://bubot_description/meshes/right_arm_wrist_roll_link.STL" />
      </geometry>
      <material
        name="">
        <color
          rgba="0.752941176470588 0.752941176470588 0.752941176470588 1" />
      </material>
    </visual>
    <collision>
      <origin
        xyz="0 0 0"
        rpy="0 0 0" />
      <geometry>
        <mesh
          filename="package://bubot_description/meshes/right_arm_wrist_roll_link.STL" />
      </geometry>
    </collision>
  </link>
  <joint
    name="right_arm_wrist_roll_joint"
    type="revolute">
    <origin
      xyz="0 0 -0.0545"
      rpy="0 0 0" />
    <parent
      link="right_arm_forearm_yaw_link" />
    <child
      link="right_arm_wrist_roll_link" />
    <axis
      xyz="1 0 0" />
    <limit
      lower="-0.5"
      upper="1.57"
      effort="10"
      velocity="1" />
    
      
  </joint>
  <link
    name="right_gripper_link">
    <inertial>
      <origin
        xyz="-0.000991234470215046 -0.0261290792276228 -0.0215782036495957"
        rpy="0 0 0" />
      <mass
        value="0.0259118393412762" />
      <inertia
        ixx="2.26169168884705E-05"
        ixy="6.71118221152274E-07"
        ixz="5.54230043124119E-07"
        iyy="2.68146617276616E-05"
        iyz="-6.49688576008527E-06"
        izz="1.44697672737526E-05" />
    </inertial>
    <visual>
      <origin
        xyz="0 0 0"
        rpy="0 0 0" />
      <geometry>
        <mesh
          filename="package://bubot_description/meshes/right_gripper_link.STL" />
      </geometry>
      <material
        name="">
        <color
          rgba="0.752941176470588 0.752941176470588 0.752941176470588 1" />
      </material>
    </visual>
    <collision>
      <origin
        xyz="0 0 0"
        rpy="0 0 0" />
      <geometry>
        <mesh
          filename="package://bubot_description/meshes/right_gripper_link.STL" />
      </geometry>
    </collision>
  </link>
  <joint
    name="right_gripper_joint"
    type="revolute">
    <origin
      xyz="0.0001 -0.008 -0.057"
      rpy="0 0 0" />
    <parent
      link="right_arm_wrist_roll_link" />
    <child
      link="right_gripper_link" />
    <axis
      xyz="1 0 0" />
    <limit
      lower="0"
      upper="1.57"
      effort="10"
      velocity="1" />
    
      
  </joint>
</robot>